{"time":"2025-03-30T09:51:31.9488289+03:00","level":"INFO","msg":"stream: starting","core version":"0.19.3","symlink path":"D:\\checkinfour\\CheckFour\\FourInRow\\wandb\\run-20250330_095131-uwmiti96\\logs\\debug-core.log"}
{"time":"2025-03-30T09:51:32.4927501+03:00","level":"INFO","msg":"created new stream","id":"uwmiti96"}
{"time":"2025-03-30T09:51:32.4933488+03:00","level":"INFO","msg":"stream: started","id":"uwmiti96"}
{"time":"2025-03-30T09:51:32.4933488+03:00","level":"INFO","msg":"writer: Do: started","stream_id":"uwmiti96"}
{"time":"2025-03-30T09:51:32.4933488+03:00","level":"INFO","msg":"handler: started","stream_id":"uwmiti96"}
{"time":"2025-03-30T09:51:32.4933488+03:00","level":"INFO","msg":"sender: started","stream_id":"uwmiti96"}
{"time":"2025-03-30T09:51:32.8585026+03:00","level":"INFO","msg":"Starting system monitor"}
{"time":"2025-03-31T15:42:13.9378824+03:00","level":"INFO","msg":"api: retrying error","error":"Post \"https://api.wandb.ai/files/yoavnave-/CheckFour/uwmiti96/file_stream\": dial tcp 35.186.228.49:443: connectex: A connection attempt failed because the connected party did not properly respond after a period of time, or established connection failed because connected host has failed to respond."}
{"time":"2025-03-31T21:19:57.102102+03:00","level":"INFO","msg":"api: retrying error","error":"Post \"https://api.wandb.ai/files/yoavnave-/CheckFour/uwmiti96/file_stream\": dial tcp 35.186.228.49:443: connectex: A connection attempt failed because the connected party did not properly respond after a period of time, or established connection failed because connected host has failed to respond."}
